Workbook

Sheet README
A1: Monthly Revenue Forecasting & Budget Variance - Excel workbook
A2: Real Walmart weekly sales (45 stores, Feb 2010 - Oct 2012), allocated to months in SQL. Budget = assumption.
A4: Sheet | B4: What it does
A5: Dashboard | B5: Headline KPIs, key findings and two charts.
A6: Assumptions | B6: EDIT HERE: growth targets by store type and the trading-day option. Everything else recalculates.
A7: Budget_vs_Actual | B7: FY2013 by month: last-year actual, budget, actual, variance, status, forecast and latest estimate.
A8: Store_BvA | B8: Every store: YTD budget vs actual, rank, revenue per sq ft, full-year latest estimate; summary by store type.
A9: Dept_BvA | B9: 81 departments: YTD budget vs actual and which departments move the total most.
A10: Excel_Forecast | B10: Seasonal index x trend forecast built with FORECAST/INDEX formulas; backtest MAPE vs budget and Python.
A11: Holidays | B11: Holiday vs normal weeks and the five biggest weeks (LARGE + INDEX/MATCH).
A12: Monthly_Data | B12: Store x month revenue (Feb 2010 - Sep 2012), from the SQL view vw_monthly_store.
A13: Dept_Data | B13: Department x store type x month revenue.
A14: Forecast_Data | B14: Forecasts written by the Python notebook (backtest and Oct 2012 - Jan 2013).
A15: Weekly_Total | B15: Company total sales per week with Walmart's holiday flag.
... A20: Sign convention | B20: Variance = actual - budget. Positive = favourable (revenue above budget).

Sheet Dashboard
A1: Walmart FY2013 Revenue: Budget vs Actual & Forecast
A2: Real Walmart sales, 45 stores | FY2013 = Feb 2012 - Jan 2013 | budget = assumption (see Assumptions sheet)
B4: FY2012 revenue (last full year) | C4: =SUMIFS(Monthly_Data!$G$2:$G$1441,Monthly_Data!$E$2:$E$1441,2012) -> 2.4599452e+09 | E4: FY2013 YTD actual (Feb-Sep) | F4: =Budget_vs_Actual!H19 -> 1.6341325e+09 | H4: YTD growth vs last year | I4: =Budget_vs_Actual!H19/SUMIFS(Monthly_Data!$G$2:$G$1441,Monthly_Data!$E$2:$E$1441,2012,Monthly_Data!$F$2:$F$1441,"<=8")-1 -> 0.032161246
B6: FY2013 YTD budget | C6: =Budget_vs_Actual!G19 -> 1.6246239e+09 | E6: YTD variance vs budget | F6: =Budget_vs_Actual!I19 -> 9508682.1 | H6: YTD variance % | I6: =Budget_vs_Actual!J19 -> 0.0058528514
B8: Full-year budget | C8: =Budget_vs_Actual!G17 -> 2.5242648e+09 | E8: Latest estimate (actual + forecast) | F8: =Budget_vs_Actual!M17 -> 2.518676e+09 | H8: Latest estimate vs budget | I8: =Budget_vs_Actual!J17 -> -0.0022140305
B10: Stores on / above budget (YTD) | C10: =COUNTIF(Store_BvA!K5:K49,"On / above") -> 32 | E10: Leap-day sales in Feb 2012 | F10: =Budget_vs_Actual!H5/29 -> 6869003.9 | H10: Best backtest MAPE (Holt-Winters) | I10: =Excel_Forecast!P25 -> 0.012709598
B12: Key findings
B13: 1. YTD revenue is slightly ahead of budget, but most of February's beat is the extra leap day (switch the trading-day option on the Assumptions sheet to see it).
B14: 2. Momentum slowed: Feb-May beat budget, Jun-Aug fell behind.
B15: 3. Type A stores (3% target) are just behind budget; Types B and C beat lower targets.
B16: 4. Store 14 alone is about $7.7M behind - almost as much as the company's whole YTD lead.
B17: 5. The forecast puts the full year within about 1% of budget; October and November carry the most risk.
B19: Sheets: Assumptions (change growth targets) | Budget_vs_Actual | Store_BvA | Dept_BvA | Excel_Forecast | Holidays | data sheets | Cleaning_Log

Sheet Assumptions
A1: Budget Assumptions
A2: Change the yellow cells - every budget and variance in the workbook updates.
B4: Store type | C4: FY2013 growth target | D4: Rationale
B5: A | C5: 0.03 | D5: Large supercenters - main growth driver
B6: B | C6: 0.02 | D6: Mid-size stores - modest growth
B7: C | C7: 0.015 | D7: Small stores - low growth
B9: Adjust budget for trading days? | D9: No
B10: No = budget is last year x (1 + growth) - the method used in SQL and Python.
B11: Yes = also scales each month by its number of days (fixes the Feb 2012 leap day: 29 vs 28 days).
B13: Budget method
B14: FY2013 budget (Feb 2012 - Jan 2013) = FY2012 actual for the same store / month x (1 + growth target for the store type).
B15: These targets are ASSUMPTIONS for the project - Walmart's internal budget is not public. All sales figures are real.

Sheet Budget_vs_Actual
A1: FY2013 Budget vs Actual, by Month
A2: Actuals Feb - Sep 2012; Oct 2012 - Jan 2013 use the Python Holt-Winters forecast. Positive variance = favourable.
A4: Month | B4: Fiscal month | C4: LY actual - Type A | D4: LY actual - Type B | E4: LY actual - Type C | F4: Day factor | G4: Budget | H4: Actual | I4: Variance | J4: Variance % | K4: Status | L4: Forecast | M4: Latest estimate | N4: LE vs budget | O4: Cumulative LE vs budget
A5: 40940 | B5: 1 | C5: =SUMIFS(Monthly_Data!$G$2:$G$1441,Monthly_Data!$E$2:$E$1441,2012,Monthly_Data!$F$2:$F$1441,$B5,Monthly_Data!$B$2:$B$1441,"A") -> 1.2059751e+08 | D5: =SUMIFS(Monthly_Data!$G$2:$G$1441,Monthly_Data!$E$2:$E$1441,2012,Monthly_Data!$F$2:$F$1441,$B5,Monthly_Data!$B$2:$B$1441,"B") -> 54719002 | E5: =SUMIFS(Monthly_Data!$G$2:$G$1441,Monthly_Data!$E$2:$E$1441,2012,Monthly_Data!$F$2:$F$1441,$B5,Monthly_Data!$B$2:$B$1441,"C") -> 11369458 | F5: =IF(Assumptions!$D$9="Yes",DAY(EOMONTH($A5,0))/DAY(EOMONTH(EDATE($A5,-12),0)),1) -> 1 | G5: =(C5*(1+Assumptions!$C$5)+D5*(1+Assumptions!$C$6)+E5*(1+Assumptions!$C$7))*F5 -> 1.9156881e+08 | H5: =IF(COUNTIFS(Monthly_Data!$E$2:$E$1441,2013,Monthly_Data!$F$2:$F$1441,$B5)=0,"",SUMIFS(Monthly_Data!$G$2:$G$1441,Monthly_Data!$E$2:$E$1441,2013,Monthly_Data!$F$2:$F$1441,$B5)) -> 1.9920111e+08 | I5: =IF(H5="","",H5-G5) -> 7632299.4 | J5: =IF(H5="","",I5/G5) -> 0.039841033 | K5: =IF(H5="","Forecast",IF(I5>=0,"Favourable","Unfavourable")) -> Favourable | L5: =IF(H5<>"","",SUMIFS(Forecast_Data!$G$2:$G$237,Forecast_Data!$A$2:$A$237,"Total",Forecast_Data!$E$2:$E$237,"Forecast",Forecast_Data!$F$2:$F$237,$A5)) | M5: =IF(H5<>"",H5,L5) -> 1.9920111e+08 | N5: =M5-G5 -> 7632299.4 | O5: =SUM($N$5:N5) -> 7632299.4
A6: 40969 | B6: 2 | C6: =SUMIFS(Monthly_Data!$G$2:$G$1441,Monthly_Data!$E$2:$E$1441,2012,Monthly_Data!$F$2:$F$1441,$B6,Monthly_Data!$B$2:$B$1441,"A") -> 1.2689357e+08 | D6: =SUMIFS(Monthly_Data!$G$2:$G$1441,Monthly_Data!$E$2:$E$1441,2012,Monthly_Data!$F$2:$F$1441,$B6,Monthly_Data!$B$2:$B$1441,"B") -> 57333123 | E6: =SUMIFS(Monthly_Data!$G$2:$G$1441,Monthly_Data!$E$2:$E$1441,2012,Monthly_Data!$F$2:$F$1441,$B6,Monthly_Data!$B$2:$B$1441,"C") -> 12245780 | F6: =IF(Assumptions!$D$9="Yes",DAY(EOMONTH($A6,0))/DAY(EOMONTH(EDATE($A6,-12),0)),1) -> 1 | G6: =(C6*(1+Assumptions!$C$5)+D6*(1+Assumptions!$C$6)+E6*(1+Assumptions!$C$7))*F6 -> 2.0160962e+08 | H6: =IF(COUNTIFS(Monthly_Data!$E$2:$E$1441,2013,Monthly_Data!$F$2:$F$1441,$B6)=0,"",SUMIFS(Monthly_Data!$G$2:$G$1441,Monthly_Data!$E$2:$E$1441,2013,Monthly_Data!$F$2:$F$1441,$B6)) -> 2.0568067e+08 | I6: =IF(H6="","",H6-G6) -> 4071046.8 | J6: =IF(H6="","",I6/G6) -> 0.020192721 | K6: =IF(H6="","Forecast",IF(I6>=0,"Favourable","Unfavourable")) -> Favourable | L6: =IF(H6<>"","",SUMIFS(Forecast_Data!$G$2:$G$237,Forecast_Data!$A$2:$A$237,"Total",Forecast_Data!$E$2:$E$237,"Forecast",Forecast_Data!$F$2:$F$237,$A6)) | M6: =IF(H6<>"",H6,L6) -> 2.0568067e+08 | N6: =M6-G6 -> 4071046.8 | O6: =SUM($N$5:N6) -> 11703346
A7: 41000 | B7: 3 | C7: =SUMIFS(Monthly_Data!$G$2:$G$1441,Monthly_Data!$E$2:$E$1441,2012,Monthly_Data!$F$2:$F$1441,$B7,Monthly_Data!$B$2:$B$1441,"A") -> 1.2677763e+08 | D7: =SUMIFS(Monthly_Data!$G$2:$G$1441,Monthly_Data!$E$2:$E$1441,2012,Monthly_Data!$F$2:$F$1441,$B7,Monthly_Data!$B$2:$B$1441,"B") -> 57128407 | E7: =SUMIFS(Monthly_Data!$G$2:$G$1441,Monthly_Data!$E$2:$E$1441,2012,Monthly_Data!$F$2:$F$1441,$B7,Monthly_Data!$B$2:$B$1441,"C") -> 12064480 | F7: =IF(Assumptions!$D$9="Yes",DAY(EOMONTH($A7,0))/DAY(EOMONTH(EDATE($A7,-12),0)),1) -> 1 | G7: =(C7*(1+Assumptions!$C$5)+D7*(1+Assumptions!$C$6)+E7*(1+Assumptions!$C$7))*F7 -> 2.0109738e+08 | H7: =IF(COUNTIFS(Monthly_Data!$E$2:$E$1441,2013,Monthly_Data!$F$2:$F$1441,$B7)=0,"",SUMIFS(Monthly_Data!$G$2:$G$1441,Monthly_Data!$E$2:$E$1441,2013,Monthly_Data!$F$2:$F$1441,$B7)) -> 2.014738e+08 | I7: =IF(H7="","",H7-G7) -> 376426.27 | J7: =IF(H7="","",I7/G7) -> 0.0018718607 | K7: =IF(H7="","Forecast",IF(I7>=0,"Favourable","Unfavourable")) -> Favourable | L7: =IF(H7<>"","",SUMIFS(Forecast_Data!$G$2:$G$237,Forecast_Data!$A$2:$A$237,"Total",Forecast_Data!$E$2:$E$237,"Forecast",Forecast_Data!$F$2:$F$237,$A7)) | M7: =IF(H7<>"",H7,L7) -> 2.014738e+08 | N7: =M7-G7 -> 376426.27 | O7: =SUM($N$5:N7) -> 12079772
A8: 41030 | B8: 4 | C8: =SUMIFS(Monthly_Data!$G$2:$G$1441,Monthly_Data!$E$2:$E$1441,2012,Monthly_Data!$F$2:$F$1441,$B8,Monthly_Data!$B$2:$B$1441,"A") -> 1.3096515e+08 | D8: =SUMIFS(Monthly_Data!$G$2:$G$1441,Monthly_Data!$E$2:$E$1441,2012,Monthly_Data!$F$2:$F$1441,$B8,Monthly_Data!$B$2:$B$1441,"B") -> 59312098 | E8: =SUMIFS(Monthly_Data!$G$2:$G$1441,Monthly_Data!$E$2:$E$1441,2012,Monthly_Data!$F$2:$F$1441,$B8,Monthly_Data!$B$2:$B$1441,"C") -> 12546051 | F8: =IF(Assumptions!$D$9="Yes",DAY(EOMONTH($A8,0))/DAY(EOMONTH(EDATE($A8,-12),0)),1) -> 1 | G8: =(C8*(1+Assumptions!$C$5)+D8*(1+Assumptions!$C$6)+E8*(1+Assumptions!$C$7))*F8 -> 2.0812669e+08 | H8: =IF(COUNTIFS(Monthly_Data!$E$2:$E$1441,2013,Monthly_Data!$F$2:$F$1441,$B8)=0,"",SUMIFS(Monthly_Data!$G$2:$G$1441,Monthly_Data!$E$2:$E$1441,2013,Monthly_Data!$F$2:$F$1441,$B8)) -> 2.0995467e+08 | I8: =IF(H8="","",H8-G8) -> 1827974.5 | J8: =IF(H8="","",I8/G8) -> 0.0087829894 | K8: =IF(H8="","Forecast",IF(I8>=0,"Favourable","Unfavourable")) -> Favourable | L8: =IF(H8<>"","",SUMIFS(Forecast_Data!$G$2:$G$237,Forecast_Data!$A$2:$A$237,"Total",Forecast_Data!$E$2:$E$237,"Forecast",Forecast_Data!$F$2:$F$237,$A8)) | M8: =IF(H8<>"",H8,L8) -> 2.0995467e+08 | N8: =M8-G8 -> 1827974.5 | O8: =SUM($N$5:N8) -> 13907747
A9: 41061 | B9: 5 | C9: =SUMIFS(Monthly_Data!$G$2:$G$1441,Monthly_Data!$E$2:$E$1441,2012,Monthly_Data!$F$2:$F$1441,$B9,Monthly_Data!$B$2:$B$1441,"A") -> 1.3029906e+08 | D9: =SUMIFS(Monthly_Data!$G$2:$G$1441,Monthly_Data!$E$2:$E$1441,2012,Monthly_Data!$F$2:$F$1441,$B9,Monthly_Data!$B$2:$B$1441,"B") -> 60425579 | E9: =SUMIFS(Monthly_Data!$G$2:$G$1441,Monthly_Data!$E$2:$E$1441,2012,Monthly_Data!$F$2:$F$1441,$B9,Monthly_Data!$B$2:$B$1441,"C") -> 11960625 | F9: =IF(Assumptions!$D$9="Yes",DAY(EOMONTH($A9,0))/DAY(EOMONTH(EDATE($A9,-12),0)),1) -> 1 | G9: =(C9*(1+Assumptions!$C$5)+D9*(1+Assumptions!$C$6)+E9*(1+Assumptions!$C$7))*F9 -> 2.0798216e+08 | H9: =IF(COUNTIFS(Monthly_Data!$E$2:$E$1441,2013,Monthly_Data!$F$2:$F$1441,$B9)=0,"",SUMIFS(Monthly_Data!$G$2:$G$1441,Monthly_Data!$E$2:$E$1441,2013,Monthly_Data!$F$2:$F$1441,$B9)) -> 2.0654792e+08 | I9: =IF(H9="","",H9-G9) -> -1434237.1 | J9: =IF(H9="","",I9/G9) -> -0.0068959621 | K9: =IF(H9="","Forecast",IF(I9>=0,"Favourable","Unfavourable")) -> Unfavourable | L9: =IF(H9<>"","",SUMIFS(Forecast_Data!$G$2:$G$237,Forecast_Data!$A$2:$A$237,"Total",Forecast_Data!$E$2:$E$237,"Forecast",Forecast_Data!$F$2:$F$237,$A9)) | M9: =IF(H9<>"",H9,L9) -> 2.0654792e+08 | N9: =M9-G9 -> -1434237.1 | O9: =SUM($N$5:N9) -> 12473510
A10: 41091 | B10: 6 | C10: =SUMIFS(Monthly_Data!$G$2:$G$1441,Monthly_Data!$E$2:$E$1441,2012,Monthly_Data!$F$2:$F$1441,$B10,Monthly_Data!$B$2:$B$1441,"A") -> 1.3099986e+08 | D10: =SUMIFS(Monthly_Data!$G$2:$G$1441,Monthly_Data!$E$2:$E$1441,2012,Monthly_Data!$F$2:$F$1441,$B10,Monthly_Data!$B$2:$B$1441,"B") -> 59719812 | E10: =SUMIFS(Monthly_Data!$G$2:$G$1441,Monthly_Data!$E$2:$E$1441,2012,Monthly_Data!$F$2:$F$1441,$B10,Monthly_Data!$B$2:$B$1441,"C") -> 12128848 | F10: =IF(Assumptions!$D$9="Yes",DAY(EOMONTH($A10,0))/DAY(EOMONTH(EDATE($A10,-12),0)),1) -> 1 | G10: =(C10*(1+Assumptions!$C$5)+D10*(1+Assumptions!$C$6)+E10*(1+Assumptions!$C$7))*F10 -> 2.0815484e+08 | H10: =IF(COUNTIFS(Monthly_Data!$E$2:$E$1441,2013,Monthly_Data!$F$2:$F$1441,$B10)=0,"",SUMIFS(Monthly_Data!$G$2:$G$1441,Monthly_Data!$E$2:$E$1441,2013,Monthly_Data!$F$2:$F$1441,$B10)) -> 2.0732239e+08 | I10: =IF(H10="","",H10-G10) -> -832448.3 | J10: =IF(H10="","",I10/G10) -> -0.0039991782 | K10: =IF(H10="","Forecast",IF(I10>=0,"Favourable","Unfavourable")) -> Unfavourable | L10: =IF(H10<>"","",SUMIFS(Forecast_Data!$G$2:$G$237,Forecast_Data!$A$2:$A$237,"Total",Forecast_Data!$E$2:$E$237,"Forecast",Forecast_Data!$F$2:$F$237,$A10)) | M10: =IF(H10<>"",H10,L10) -> 2.0732239e+08 | N10: =M10-G10 -> -832448.3 | O10: =SUM($N$5:N10) -> 11641062
A11: 41122 | B11: 7 | C11: =SUMIFS(Monthly_Data!$G$2:$G$1441,Monthly_Data!$E$2:$E$1441,2012,Monthly_Data!$F$2:$F$1441,$B11,Monthly_Data!$B$2:$B$1441,"A") -> 1.3422109e+08 | D11: =SUMIFS(Monthly_Data!$G$2:$G$1441,Monthly_Data!$E$2:$E$1441,2012,Monthly_Data!$F$2:$F$1441,$B11,Monthly_Data!$B$2:$B$1441,"B") -> 60833543 | E11: =SUMIFS(Monthly_Data!$G$2:$G$1441,Monthly_Data!$E$2:$E$1441,2012,Monthly_Data!$F$2:$F$1441,$B11,Monthly_Data!$B$2:$B$1441,"C") -> 12237868 | F11: =IF(Assumptions!$D$9="Yes",DAY(EOMONTH($A11,0))/DAY(EOMONTH(EDATE($A11,-12),0)),1) -> 1 | G11: =(C11*(1+Assumptions!$C$5)+D11*(1+Assumptions!$C$6)+E11*(1+Assumptions!$C$7))*F11 -> 2.1271937e+08 | H11: =IF(COUNTIFS(Monthly_Data!$E$2:$E$1441,2013,Monthly_Data!$F$2:$F$1441,$B11)=0,"",SUMIFS(Monthly_Data!$G$2:$G$1441,Monthly_Data!$E$2:$E$1441,2013,Monthly_Data!$F$2:$F$1441,$B11)) -> 2.0971597e+08 | I11: =IF(H11="","",H11-G11) -> -3003406.5 | J11: =IF(H11="","",I11/G11) -> -0.014119102 | K11: =IF(H11="","Forecast",IF(I11>=0,"Favourable","Unfavourable")) -> Unfavourable | L11: =IF(H11<>"","",SUMIFS(Forecast_Data!$G$2:$G$237,Forecast_Data!$A$2:$A$237,"Total",Forecast_Data!$E$2:$E$237,"Forecast",Forecast_Data!$F$2:$F$237,$A11)) | M11: =IF(H11<>"",H11,L11) -> 2.0971597e+08 | N11: =M11-G11 -> -3003406.5 | O11: =SUM($N$5:N11) -> 8637655.2
A12: 41153 | B12: 8 | C12: =SUMIFS(Monthly_Data!$G$2:$G$1441,Monthly_Data!$E$2:$E$1441,2012,Monthly_Data!$F$2:$F$1441,$B12,Monthly_Data!$B$2:$B$1441,"A") -> 1.2193085e+08 | D12: =SUMIFS(Monthly_Data!$G$2:$G$1441,Monthly_Data!$E$2:$E$1441,2012,Monthly_Data!$F$2:$F$1441,$B12,Monthly_Data!$B$2:$B$1441,"B") -> 54724154 | E12: =SUMIFS(Monthly_Data!$G$2:$G$1441,Monthly_Data!$E$2:$E$1441,2012,Monthly_Data!$F$2:$F$1441,$B12,Monthly_Data!$B$2:$B$1441,"C") -> 11780861 | F12: =IF(Assumptions!$D$9="Yes",DAY(EOMONTH($A12,0))/DAY(EOMONTH(EDATE($A12,-12),0)),1) -> 1 | G12: =(C12*(1+Assumptions!$C$5)+D12*(1+Assumptions!$C$6)+E12*(1+Assumptions!$C$7))*F12 -> 1.9336499e+08 | H12: =IF(COUNTIFS(Monthly_Data!$E$2:$E$1441,2013,Monthly_Data!$F$2:$F$1441,$B12)=0,"",SUMIFS(Monthly_Data!$G$2:$G$1441,Monthly_Data!$E$2:$E$1441,2013,Monthly_Data!$F$2:$F$1441,$B12)) -> 1.9423601e+08 | I12: =IF(H12="","",H12-G12) -> 871026.91 | J12: =IF(H12="","",I12/G12) -> 0.0045045741 | K12: =IF(H12="","Forecast",IF(I12>=0,"Favourable","Unfavourable")) -> Favourable | L12: =IF(H12<>"","",SUMIFS(Forecast_Data!$G$2:$G$237,Forecast_Data!$A$2:$A$237,"Total",Forecast_Data!$E$2:$E$237,"Forecast",Forecast_Data!$F$2:$F$237,$A12)) | M12: =IF(H12<>"",H12,L12) -> 1.9423601e+08 | N12: =M12-G12 -> 871026.91 | O12: =SUM($N$5:N12) -> 9508682.1
A13: 41183 | B13: 9 | C13: =SUMIFS(Monthly_Data!$G$2:$G$1441,Monthly_Data!$E$2:$E$1441,2012,Monthly_Data!$F$2:$F$1441,$B13,Monthly_Data!$B$2:$B$1441,"A") -> 1.3208744e+08 | D13: =SUMIFS(Monthly_Data!$G$2:$G$1441,Monthly_Data!$E$2:$E$1441,2012,Monthly_Data!$F$2:$F$1441,$B13,Monthly_Data!$B$2:$B$1441,"B") -> 59426998 | E13: =SUMIFS(Monthly_Data!$G$2:$G$1441,Monthly_Data!$E$2:$E$1441,2012,Monthly_Data!$F$2:$F$1441,$B13,Monthly_Data!$B$2:$B$1441,"C") -> 12599222 | F13: =IF(Assumptions!$D$9="Yes",DAY(EOMONTH($A13,0))/DAY(EOMONTH(EDATE($A13,-12),0)),1) -> 1 | G13: =(C13*(1+Assumptions!$C$5)+D13*(1+Assumptions!$C$6)+E13*(1+Assumptions!$C$7))*F13 -> 2.0945381e+08 | H13: =IF(COUNTIFS(Monthly_Data!$E$2:$E$1441,2013,Monthly_Data!$F$2:$F$1441,$B13)=0,"",SUMIFS(Monthly_Data!$G$2:$G$1441,Monthly_Data!$E$2:$E$1441,2013,Monthly_Data!$F$2:$F$1441,$B13)) | I13: =IF(H13="","",H13-G13) | J13: =IF(H13="","",I13/G13) | K13: =IF(H13="","Forecast",IF(I13>=0,"Favourable","Unfavourable")) -> Forecast | L13: =IF(H13<>"","",SUMIFS(Forecast_Data!$G$2:$G$237,Forecast_Data!$A$2:$A$237,"Total",Forecast_Data!$E$2:$E$237,"Forecast",Forecast_Data!$F$2:$F$237,$A13)) -> 2.0338686e+08 | M13: =IF(H13<>"",H13,L13) -> 2.0338686e+08 | N13: =M13-G13 -> -6066950.7 | O13: =SUM($N$5:N13) -> 3441731.4
A14: 41214 | B14: 10 | C14: =SUMIFS(Monthly_Data!$G$2:$G$1441,Monthly_Data!$E$2:$E$1441,2012,Monthly_Data!$F$2:$F$1441,$B14,Monthly_Data!$B$2:$B$1441,"A") -> 1.4354187e+08 | D14: =SUMIFS(Monthly_Data!$G$2:$G$1441,Monthly_Data!$E$2:$E$1441,2012,Monthly_Data!$F$2:$F$1441,$B14,Monthly_Data!$B$2:$B$1441,"B") -> 68716495 | E14: =SUMIFS(Monthly_Data!$G$2:$G$1441,Monthly_Data!$E$2:$E$1441,2012,Monthly_Data!$F$2:$F$1441,$B14,Monthly_Data!$B$2:$B$1441,"C") -> 12330585 | F14: =IF(Assumptions!$D$9="Yes",DAY(EOMONTH($A14,0))/DAY(EOMONTH(EDATE($A14,-12),0)),1) -> 1 | G14: =(C14*(1+Assumptions!$C$5)+D14*(1+Assumptions!$C$6)+E14*(1+Assumptions!$C$7))*F14 -> 2.3045449e+08 | H14: =IF(COUNTIFS(Monthly_Data!$E$2:$E$1441,2013,Monthly_Data!$F$2:$F$1441,$B14)=0,"",SUMIFS(Monthly_Data!$G$2:$G$1441,Monthly_Data!$E$2:$E$1441,2013,Monthly_Data!$F$2:$F$1441,$B14)) | I14: =IF(H14="","",H14-G14) | J14: =IF(H14="","",I14/G14) | K14: =IF(H14="","Forecast",IF(I14>=0,"Favourable","Unfavourable")) -> Forecast | L14: =IF(H14<>"","",SUMIFS(Forecast_Data!$G$2:$G$237,Forecast_Data!$A$2:$A$237,"Total",Forecast_Data!$E$2:$E$237,"Forecast",Forecast_Data!$F$2:$F$237,$A14)) -> 2.2618539e+08 | M14: =IF(H14<>"",H14,L14) -> 2.2618539e+08 | N14: =M14-G14 -> -4269104.7 | O14: =SUM($N$5:N14) -> -827373.24
A15: 41244 | B15: 11 | C15: =SUMIFS(Monthly_Data!$G$2:$G$1441,Monthly_Data!$E$2:$E$1441,2012,Monthly_Data!$F$2:$F$1441,$B15,Monthly_Data!$B$2:$B$1441,"A") -> 1.656726e+08 | D15: =SUMIFS(Monthly_Data!$G$2:$G$1441,Monthly_Data!$E$2:$E$1441,2012,Monthly_Data!$F$2:$F$1441,$B15,Monthly_Data!$B$2:$B$1441,"B") -> 80876543 | E15: =SUMIFS(Monthly_Data!$G$2:$G$1441,Monthly_Data!$E$2:$E$1441,2012,Monthly_Data!$F$2:$F$1441,$B15,Monthly_Data!$B$2:$B$1441,"C") -> 12672199 | F15: =IF(Assumptions!$D$9="Yes",DAY(EOMONTH($A15,0))/DAY(EOMONTH(EDATE($A15,-12),0)),1) -> 1 | G15: =(C15*(1+Assumptions!$C$5)+D15*(1+Assumptions!$C$6)+E15*(1+Assumptions!$C$7))*F15 -> 2.6599913e+08 | H15: =IF(COUNTIFS(Monthly_Data!$E$2:$E$1441,2013,Monthly_Data!$F$2:$F$1441,$B15)=0,"",SUMIFS(Monthly_Data!$G$2:$G$1441,Monthly_Data!$E$2:$E$1441,2013,Monthly_Data!$F$2:$F$1441,$B15)) | I15: =IF(H15="","",H15-G15) | J15: =IF(H15="","",I15/G15) | K15: =IF(H15="","Forecast",IF(I15>=0,"Favourable","Unfavourable")) -> Forecast | L15: =IF(H15<>"","",SUMIFS(Forecast_Data!$G$2:$G$237,Forecast_Data!$A$2:$A$237,"Total",Forecast_Data!$E$2:$E$237,"Forecast",Forecast_Data!$F$2:$F$237,$A15)) -> 2.6519033e+08 | M15: =IF(H15<>"",H15,L15) -> 2.6519033e+08 | N15: =M15-G15 -> -808800.58 | O15: =SUM($N$5:N15) -> -1636173.8
A16: 41275 | B16: 12 | C16: =SUMIFS(Monthly_Data!$G$2:$G$1441,Monthly_Data!$E$2:$E$1441,2012,Monthly_Data!$F$2:$F$1441,$B16,Monthly_Data!$B$2:$B$1441,"A") -> 1.2161815e+08 | D16: =SUMIFS(Monthly_Data!$G$2:$G$1441,Monthly_Data!$E$2:$E$1441,2012,Monthly_Data!$F$2:$F$1441,$B16,Monthly_Data!$B$2:$B$1441,"B") -> 54044521 | E16: =SUMIFS(Monthly_Data!$G$2:$G$1441,Monthly_Data!$E$2:$E$1441,2012,Monthly_Data!$F$2:$F$1441,$B16,Monthly_Data!$B$2:$B$1441,"C") -> 13144232 | F16: =IF(Assumptions!$D$9="Yes",DAY(EOMONTH($A16,0))/DAY(EOMONTH(EDATE($A16,-12),0)),1) -> 1 | G16: =(C16*(1+Assumptions!$C$5)+D16*(1+Assumptions!$C$6)+E16*(1+Assumptions!$C$7))*F16 -> 1.937335e+08 | H16: =IF(COUNTIFS(Monthly_Data!$E$2:$E$1441,2013,Monthly_Data!$F$2:$F$1441,$B16)=0,"",SUMIFS(Monthly_Data!$G$2:$G$1441,Monthly_Data!$E$2:$E$1441,2013,Monthly_Data!$F$2:$F$1441,$B16)) | I16: =IF(H16="","",H16-G16) | J16: =IF(H16="","",I16/G16) | K16: =IF(H16="","Forecast",IF(I16>=0,"Favourable","Unfavourable")) -> Forecast | L16: =IF(H16<>"","",SUMIFS(Forecast_Data!$G$2:$G$237,Forecast_Data!$A$2:$A$237,"Total",Forecast_Data!$E$2:$E$237,"Forecast",Forecast_Data!$F$2:$F$237,$A16)) -> 1.8978087e+08 | M16: =IF(H16<>"",H16,L16) -> 1.8978087e+08 | N16: =M16-G16 -> -3952625.4 | O16: =SUM($N$5:N16) -> -5588799.2
A17: Full year | C17: =SUM(C5:C16) -> 1.5856048e+09 | D17: =SUM(D5:D16) -> 7.2726028e+08 | E17: =SUM(E5:E16) -> 1.4708021e+08 | G17: =SUM(G5:G16) -> 2.5242648e+09 | H17: =SUM(H5:H16) -> 1.6341325e+09 | I17: =SUM(I5:I16) -> 9508682.1 | J17: =IFERROR(N17/G17,0) -> -0.0022140305 | L17: =SUM(L5:L16) -> 8.8454345e+08 | M17: =SUM(M5:M16) -> 2.518676e+09 | N17: =M17-G17 -> -5588799.2
J18: J17 = full-year latest estimate vs budget
A19: Year to date (months with actuals) | G19: =SUMPRODUCT((H5:H16<>"")*G5:G16) -> 1.6246239e+09 | H19: =SUM(H5:H16) -> 1.6341325e+09 | I19: =H19-G19 -> 9508682.1 | J19: =IFERROR(I19/G19,0) -> 0.0058528514

Sheet Store_BvA
A1: Budget vs Actual by Store
A2: Year to date = Feb - Sep 2012. Full-year forecast for Oct - Jan uses each store's run-rate (Python).
A4: Store | B4: Type | C4: Size (sq ft) | D4: LY YTD (Feb-Sep 2011) | E4: LY Feb 2011 | F4: YTD budget | G4: YTD actual | H4: YTD variance | I4: Variance % | J4: Rank (1 = best) | K4: Status | L4: FY2012 revenue | M4: Revenue / sq ft | N4: Full-year budget | O4: Forecast Oct-Jan | P4: Latest estimate | Q4: LE vs budget | R4: LE vs budget %
A5: 1 | B5: A | C5: 151315 | D5: =SUMIFS(Monthly_Data!$G$2:$G$1441,Monthly_Data!$A$2:$A$1441,$A5,Monthly_Data!$E$2:$E$1441,2012,Monthly_Data!$F$2:$F$1441,"<=8") -> 52783417 | E5: =SUMIFS(Monthly_Data!$G$2:$G$1441,Monthly_Data!$A$2:$A$1441,$A5,Monthly_Data!$E$2:$E$1441,2012,Monthly_Data!$F$2:$F$1441,1) -> 6412587.8 | F5: =(D5+E5*(IF(Assumptions!$D$9="Yes",DAY(EOMONTH(DATE(2012,2,1),0))/DAY(EOMONTH(EDATE(DATE(2012,2,1),-12),0)),1)-1))*(1+IF(B5="A",Assumptions!$C$5,IF(B5="B",Assumptions!$C$6,Assumptions!$C$7))) -> 54366920 | G5: =SUMIFS(Monthly_Data!$G$2:$G$1441,Monthly_Data!$A$2:$A$1441,$A5,Monthly_Data!$E$2:$E$1441,2013) -> 55775096 | H5: =G5-F5 -> 1408176.8 | I5: =IFERROR(H5/F5,0) -> 0.025901354 | J5: =RANK(I5,$I$5:$I$49) -> 16 | K5: =IF(H5>=0,"On / above","Below") -> On / above | L5: =SUMIFS(Monthly_Data!$G$2:$G$1441,Monthly_Data!$A$2:$A$1441,$A5,Monthly_Data!$E$2:$E$1441,2012) -> 81412054 | M5: =IFERROR(L5/C5,0) -> 538.0303 | N5: =(L5+E5*(IF(Assumptions!$D$9="Yes",DAY(EOMONTH(DATE(2012,2,1),0))/DAY(EOMONTH(EDATE(DATE(2012,2,1),-12),0)),1)-1))*(1+IF(B5="A",Assumptions!$C$5,IF(B5="B",Assumptions!$C$6,Assumptions!$C$7))) -> 83854416 | O5: =SUMIFS(Forecast_Data!$G$2:$G$237,Forecast_Data!$A$2:$A$237,"Store",Forecast_Data!$C$2:$C$237,$A5) -> 30251262 | P5: =G5+O5 -> 86026359 | Q5: =P5-N5 -> 2171942.9 | R5: =IFERROR(Q5/N5,0) -> 0.025901354
A6: 2 | B6: A | C6: 202307 | D6: =SUMIFS(Monthly_Data!$G$2:$G$1441,Monthly_Data!$A$2:$A$1441,$A6,Monthly_Data!$E$2:$E$1441,2012,Monthly_Data!$F$2:$F$1441,"<=8") -> 63472374 | E6: =SUMIFS(Monthly_Data!$G$2:$G$1441,Monthly_Data!$A$2:$A$1441,$A6,Monthly_Data!$E$2:$E$1441,2012,Monthly_Data!$F$2:$F$1441,1) -> 8034181.6 | F6: =(D6+E6*(IF(Assumptions!$D$9="Yes",DAY(EOMONTH(DATE(2012,2,1),0))/DAY(EOMONTH(EDATE(DATE(2012,2,1),-12),0)),1)-1))*(1+IF(B6="A",Assumptions!$C$5,IF(B6="B",Assumptions!$C$6,Assumptions!$C$7))) -> 65376545 | G6: =SUMIFS(Monthly_Data!$G$2:$G$1441,Monthly_Data!$A$2:$A$1441,$A6,Monthly_Data!$E$2:$E$1441,2013) -> 66463323 | H6: =G6-F6 -> 1086777.8 | I6: =IFERROR(H6/F6,0) -> 0.016623359 | J6: =RANK(I6,$I$5:$I$49) -> 20 | K6: =IF(H6>=0,"On / above","Below") -> On / above | L6: =SUMIFS(Monthly_Data!$G$2:$G$1441,Monthly_Data!$A$2:$A$1441,$A6,Monthly_Data!$E$2:$E$1441,2012) -> 98854824 | M6: =IFERROR(L6/C6,0) -> 488.63769 | N6: =(L6+E6*(IF(Assumptions!$D$9="Yes",DAY(EOMONTH(DATE(2012,2,1),0))/DAY(EOMONTH(EDATE(DATE(2012,2,1),-12),0)),1)-1))*(1+IF(B6="A",Assumptions!$C$5,IF(B6="B",Assumptions!$C$6,Assumptions!$C$7))) -> 1.0182047e+08 | O6: =SUMIFS(Forecast_Data!$G$2:$G$237,Forecast_Data!$A$2:$A$237,"Store",Forecast_Data!$C$2:$C$237,$A6) -> 37049745 | P6: =G6+O6 -> 1.0351307e+08 | Q6: =P6-N6 -> 1692598.2 | R6: =IFERROR(Q6/N6,0) -> 0.016623359
A7: 3 | B7: B | C7: 37392 | D7: =SUMIFS(Monthly_Data!$G$2:$G$1441,Monthly_Data!$A$2:$A$1441,$A7,Monthly_Data!$E$2:$E$1441,2012,Monthly_Data!$F$2:$F$1441,"<=8") -> 13360975 | E7: =SUMIFS(Monthly_Data!$G$2:$G$1441,Monthly_Data!$A$2:$A$1441,$A7,Monthly_Data!$E$2:$E$1441,2012,Monthly_Data!$F$2:$F$1441,1) -> 1698422.3 | F7: =(D7+E7*(IF(Assumptions!$D$9="Yes",DAY(EOMONTH(DATE(2012,2,1),0))/DAY(EOMONTH(EDATE(DATE(2012,2,1),-12),0)),1)-1))*(1+IF(B7="A",Assumptions!$C$5,IF(B7="B",Assumptions!$C$6,Assumptions!$C$7))) -> 13628194 | G7: =SUMIFS(Monthly_Data!$G$2:$G$1441,Monthly_Data!$A$2:$A$1441,$A7,Monthly_Data!$E$2:$E$1441,2013) -> 14743074 | H7: =G7-F7 -> 1114879.8 | I7: =IFERROR(H7/F7,0) -> 0.081806859 | J7: =RANK(I7,$I$5:$I$49) -> 3 | K7: =IF(H7>=0,"On / above","Below") -> On / above | L7: =SUMIFS(Monthly_Data!$G$2:$G$1441,Monthly_Data!$A$2:$A$1441,$A7,Monthly_Data!$E$2:$E$1441,2012) -> 20877684 | M7: =IFERROR(L7/C7,0) -> 558.34627 | N7: =(L7+E7*(IF(Assumptions!$D$9="Yes",DAY(EOMONTH(DATE(2012,2,1),0))/DAY(EOMONTH(EDATE(DATE(2012,2,1),-12),0)),1)-1))*(1+IF(B7="A",Assumptions!$C$5,IF(B7="B",Assumptions!$C$6,Assumptions!$C$7))) -> 21295237 | O7: =SUMIFS(Forecast_Data!$G$2:$G$237,Forecast_Data!$A$2:$A$237,"Store",Forecast_Data!$C$2:$C$237,$A7) -> 8294259.4 | P7: =G7+O7 -> 23037334 | Q7: =P7-N7 -> 1742096.5 | R7: =IFERROR(Q7/N7,0) -> 0.081806859
A8: 4 | B8: A | C8: 205863 | D8: =SUMIFS(Monthly_Data!$G$2:$G$1441,Monthly_Data!$A$2:$A$1441,$A8,Monthly_Data!$E$2:$E$1441,2012,Monthly_Data!$F$2:$F$1441,"<=8") -> 71277070 | E8: =SUMIFS(Monthly_Data!$G$2:$G$1441,Monthly_Data!$A$2:$A$1441,$A8,Monthly_Data!$E$2:$E$1441,2012,Monthly_Data!$F$2:$F$1441,1) -> 8694824.9 | F8: =(D8+E8*(IF(Assumptions!$D$9="Yes",DAY(EOMONTH(DATE(2012,2,1),0))/DAY(EOMONTH(EDATE(DATE(2012,2,1),-12),0)),1)-1))*(1+IF(B8="A",Assumptions!$C$5,IF(B8="B",Assumptions!$C$6,Assumptions!$C$7))) -> 73415382 | G8: =SUMIFS(Monthly_Data!$G$2:$G$1441,Monthly_Data!$A$2:$A$1441,$A8,Monthly_Data!$E$2:$E$1441,2013) -> 75647659 | H8: =G8-F8 -> 2232276.8 | I8: =IFERROR(H8/F8,0) -> 0.030406118 | J8: =RANK(I8,$I$5:$I$49) -> 13 | K8: =IF(H8>=0,"On / above","Below") -> On / above | L8: =SUMIFS(Monthly_Data!$G$2:$G$1441,Monthly_Data!$A$2:$A$1441,$A8,Monthly_Data!$E$2:$E$1441,2012) -> 1.1192069e+08 | M8: =IFERROR(L8/C8,0) -> 543.66588 | N8: =(L8+E8*(IF(Assumptions!$D$9="Yes",DAY(EOMONTH(DATE(2012,2,1),0))/DAY(EOMONTH(EDATE(DATE(2012,2,1),-12),0)),1)-1))*(1+IF(B8="A",Assumptions!$C$5,IF(B8="B",Assumptions!$C$6,Assumptions!$C$7))) -> 1.1527831e+08 | O8: =SUMIFS(Forecast_Data!$G$2:$G$237,Forecast_Data!$A$2:$A$237,"Store",Forecast_Data!$C$2:$C$237,$A8) -> 43135816 | P8: =G8+O8 -> 1.1878348e+08 | Q8: =P8-N8 -> 3505165.9 | R8: =IFERROR(Q8/N8,0) -> 0.030406118
A9: 5 | B9: B | C9: 34875 | D9: =SUMIFS(Monthly_Data!$G$2:$G$1441,Monthly_Data!$A$2:$A$1441,$A9,Monthly_Data!$E$2:$E$1441,2012,Monthly_Data!$F$2:$F$1441,"<=8") -> 10607058 | E9: =SUMIFS(Monthly_Data!$G$2:$G$1441,Monthly_Data!$A$2:$A$1441,$A9,Monthly_Data!$E$2:$E$1441,2012,Monthly_Data!$F$2:$F$1441,1) -> 1292237.5 | F9: =(D9+E9*(IF(Assumptions!$D$9="Yes",DAY(EOMONTH(DATE(2012,2,1),0))/DAY(EOMONTH(EDATE(DATE(2012,2,1),-12),0)),1)-1))*(1+IF(B9="A",Assumptions!$C$5,IF(B9="B",Assumptions!$C$6,Assumptions!$C$7))) -> 10819199 | G9: =SUMIFS(Monthly_Data!$G$2:$G$1441,Monthly_Data!$A$2:$A$1441,$A9,Monthly_Data!$E$2:$E$1441,2013) -> 11587690 | H9: =G9-F9 -> 768491.32 | I9: =IFERROR(H9/F9,0) -> 0.071030334 | J9: =RANK(I9,$I$5:$I$49) -> 5 | K9: =IF(H9>=0,"On / above","Below") -> On / above | L9: =SUMIFS(Monthly_Data!$G$2:$G$1441,Monthly_Data!$A$2:$A$1441,$A9,Monthly_Data!$E$2:$E$1441,2012) -> 16606030 | M9: =IFERROR(L9/C9,0) -> 476.15858 | N9: =(L9+E9*(IF(Assumptions!$D$9="Yes",DAY(EOMONTH(DATE(2012,2,1),0))/DAY(EOMONTH(EDATE(DATE(2012,2,1),-12),0)),1)-1))*(1+IF(B9="A",Assumptions!$C$5,IF(B9="B",Assumptions!$C$6,Assumptions!$C$7))) -> 16938151 | O9: =SUMIFS(Forecast_Data!$G$2:$G$237,Forecast_Data!$A$2:$A$237,"Store",Forecast_Data!$C$2:$C$237,$A9) -> 6553583.1 | P9: =G9+O9 -> 18141274 | Q9: =P9-N9 -> 1203122.5 | R9: =IFERROR(Q9/N9,0) -> 0.071030333
A10: 6 | B10: A | C10: 202505 | D10: =SUMIFS(Monthly_Data!$G$2:$G$1441,Monthly_Data!$A$2:$A$1441,$A10,Monthly_Data!$E$2:$E$1441,2012,Monthly_Data!$F$2:$F$1441,"<=8") -> 52265802 | E10: =SUMIFS(Monthly_Data!$G$2:$G$1441,Monthly_Data!$A$2:$A$1441,$A10,Monthly_Data!$E$2:$E$1441,2012,Monthly_Data!$F$2:$F$1441,1) -> 5991331.1 | F10: =(D10+E10*(IF(Assumptions!$D$9="Yes",DAY(EOMONTH(DATE(2012,2,1),0))/DAY(EOMONTH(EDATE(DATE(2012,2,1),-12),0)),1)-1))*(1+IF(B10="A",Assumptions!$C$5,IF(B10="B",Assumptions!$C$6,Assumptions!$C$7))) -> 53833776 | G10: =SUMIFS(Monthly_Data!$G$2:$G$1441,Monthly_Data!$A$2:$A$1441,$A10,Monthly_Data!$E$2:$E$1441,2013) -> 54666446 | H10: =G10-F10 -> 832670.3 | I10: =IFERROR(H10/F10,0) -> 0.015467433 | J10: =RANK(I10,$I$5:$I$49) -> 22 | K10: =IF(H10>=0,"On / above","Below") -> On / above | L10: =SUMIFS(Monthly_Data!$G$2:$G$1441,Monthly_Data!$A$2:$A$1441,$A10,Monthly_Data!$E$2:$E$1441,2012) -> 80911035 | M10: =IFERROR(L10/C10,0) -> 399.5508 | N10: =(L10+E10*(IF(Assumptions!$D$9="Yes",DAY(EOMONTH(DATE(2012,2,1),0))/DAY(EOMONTH(EDATE(DATE(2012,2,1),-12),0)),1)-1))*(1+IF(B10="A",Assumptions!$C$5,IF(B10="B",Assumptions!$C$6,Assumptions!$C$7))) -> 83338366 | O10: =SUMIFS(Forecast_Data!$G$2:$G$237,Forecast_Data!$A$2:$A$237,"Store",Forecast_Data!$C$2:$C$237,$A10) -> 29960950 | P10: =G10+O10 -> 84627396 | Q10: =P10-N10 -> 1289030.6 | R10: =IFERROR(Q10/N10,0) -> 0.015467433
A11: 7 | B11: B | C11: 70713 | D11: =SUMIFS(Monthly_Data!$G$2:$G$1441,Monthly_Data!$A$2:$A$1441,$A11,Monthly_Data!$E$2:$E$1441,2012,Monthly_Data!$F$2:$F$1441,"<=8") -> 19615088 | E11: =SUMIFS(Monthly_Data!$G$2:$G$1441,Monthly_Data!$A$2:$A$1441,$A11,Monthly_Data!$E$2:$E$1441,2012,Monthly_Data!$F$2:$F$1441,1) -> 2234159.5 | F11: =(D11+E11*(IF(Assumptions!$D$9="Yes",DAY(EOMONTH(DATE(2012,2,1),0))/DAY(EOMONTH(EDATE(DATE(2012,2,1),-12),0)),1)-1))*(1+IF(B11="A",Assumptions!$C$5,IF(B11="B",Assumptions!$C$6,Assumptions!$C$7))) -> 20007390 | G11: =SUMIFS(Monthly_Data!$G$2:$G$1441,Monthly_Data!$A$2:$A$1441,$A11,Monthly_Data!$E$2:$E$1441,2013) -> 20733095 | H11: =G11-F11 -> 725705.08 | I11: =IFERROR(H11/F11,0) -> 0.036271851 | J11: =RANK(I11,$I$5:$I$49) -> 11 | K11: =IF(H11>=0,"On / above","Below") -> On / above | L11: =SUMIFS(Monthly_Data!$G$2:$G$1441,Monthly_Data!$A$2:$A$1441,$A11,Monthly_Data!$E$2:$E$1441,2012) -> 30937747 | M11: =IFERROR(L11/C11,0) -> 437.51145 | N11: =(L11+E11*(IF(Assumptions!$D$9="Yes",DAY(EOMONTH(DATE(2012,2,1),0))/DAY(EOMONTH(EDATE(DATE(2012,2,1),-12),0)),1)-1))*(1+IF(B11="A",Assumptions!$C$5,IF(B11="B",Assumptions!$C$6,Assumptions!$C$7))) -> 31556502 | O11: =SUMIFS(Forecast_Data!$G$2:$G$237,Forecast_Data!$A$2:$A$237,"Store",Forecast_Data!$C$2:$C$237,$A11) -> 11968019 | P11: =G11+O11 -> 32701115 | Q11: =P11-N11 -> 1144612.7 | R11: =IFERROR(Q11/N11,0) -> 0.036271851
A12: 8 | B12: A | C12: 155078 | D12: =SUMIFS(Monthly_Data!$G$2:$G$1441,Monthly_Data!$A$2:$A$1441,$A12,Monthly_Data!$E$2:$E$1441,2012,Monthly_Data!$F$2:$F$1441,"<=8") -> 30769847 | E12: =SUMIFS(Monthly_Data!$G$2:$G$1441,Monthly_Data!$A$2:$A$1441,$A12,Monthly_Data!$E$2:$E$1441,2012,Monthly_Data!$F$2:$F$1441,1) -> 3919170.1 | F12: =(D12+E12*(IF(Assumptions!$D$9="Yes",DAY(EOMONTH(DATE(2012,2,1),0))/DAY(EOMONTH(EDATE(DATE(2012,2,1),-12),0)),1)-1))*(1+IF(B12="A",Assumptions!$C$5,IF(B12="B",Assumptions!$C$6,Assumptions!$C$7))) -> 31692943 | G12: =SUMIFS(Monthly_Data!$G$2:$G$1441,Monthly_Data!$A$2:$A$1441,$A12,Monthly_Data!$E$2:$E$1441,2013) -> 32005001 | H12: =G12-F12 -> 312058.41 | I12: =IFERROR(H12/F12,0) -> 0.009846306 | J12: =RANK(I12,$I$5:$I$49) -> 25 | K12: =IF(H12>=0,"On / above","Below") -> On / above | L12: =SUMIFS(Monthly_Data!$G$2:$G$1441,Monthly_Data!$A$2:$A$1441,$A12,Monthly_Data!$E$2:$E$1441,2012) -> 47632295 | M12: =IFERROR(L12/C12,0) -> 307.15056 | N12: =(L12+E12*(IF(Assumptions!$D$9="Yes",DAY(EOMONTH(DATE(2012,2,1),0))/DAY(EOMONTH(EDATE(DATE(2012,2,1),-12),0)),1)-1))*(1+IF(B12="A",Assumptions!$C$5,IF(B12="B",Assumptions!$C$6,Assumptions!$C$7))) -> 49061264 | O12: =SUMIFS(Forecast_Data!$G$2:$G$237,Forecast_Data!$A$2:$A$237,"Store",Forecast_Data!$C$2:$C$237,$A12) -> 17539335 | P12: =G12+O12 -> 49544336 | Q12: =P12-N12 -> 483072.22 | R12: =IFERROR(Q12/N12,0) -> 0.0098463061
A13: 9 | B13: B | C13: 125833 | D13: =SUMIFS(Monthly_Data!$G$2:$G$1441,Monthly_Data!$A$2:$A$1441,$A13,Monthly_Data!$E$2:$E$1441,2012,Monthly_Data!$F$2:$F$1441,"<=8") -> 18443247 | E13: =SUMIFS(Monthly_Data!$G$2:$G$1441,Monthly_Data!$A$2:$A$1441,$A13,Monthly_Data!$E$2:$E$1441,2012,Monthly_Data!$F$2:$F$1441,1) -> 2222871.4 | F13: =(D13+E13*(IF(Assumptions!$D$9="Yes",DAY(EOMONTH(DATE(2012,2,1),0))/DAY(EOMONTH(EDATE(DATE(2012,2,1),-12),0)),1)-1))*(1+IF(B13="A",Assumptions!$C$5,IF(B13="B",Assumptions!$C$6,Assumptions!$C$7))) -> 18812112 | G13: =SUMIFS(Monthly_Data!$G$2:$G$1441,Monthly_Data!$A$2:$A$1441,$A13,Monthly_Data!$E$2:$E$1441,2013) -> 19619028 | H13: =G13-F13 -> 806916.45 | I13: =IFERROR(H13/F13,0) -> 0.042893454 | J13: =RANK(I13,$I$5:$I$49) -> 9 | K13: =IF(H13>=0,"On / above","Below") -> On / above | L13: =SUMIFS(Monthly_Data!$G$2:$G$1441,Monthly_Data!$A$2:$A$1441,$A13,Monthly_Data!$E$2:$E$1441,2012) -> 28857312 | M13: =IFERROR(L13/C13,0) -> 229.33024 | N13: =(L13+E13*(IF(Assumptions!$D$9="Yes",DAY(EOMONTH(DATE(2012,2,1),0))/DAY(EOMONTH(EDATE(DATE(2012,2,1),-12),0)),1)-1))*(1+IF(B13="A",Assumptions!$C$5,IF(B13="B",Assumptions!$C$6,Assumptions!$C$7))) -> 29434458 | O13: =SUMIFS(Forecast_Data!$G$2:$G$237,Forecast_Data!$A$2:$A$237,"Store",Forecast_Data!$C$2:$C$237,$A13) -> 11077975 | P13: =G13+O13 -> 30697003 | Q13: =P13-N13 -> 1262545.5 | R13: =IFERROR(Q13/N13,0) -> 0.042893454
A14: 10 | B14: B | C14: 126512 | D14: =SUMIFS(Monthly_Data!$G$2:$G$1441,Monthly_Data!$A$2:$A$1441,$A14,Monthly_Data!$E$2:$E$1441,2012,Monthly_Data!$F$2:$F$1441,"<=8") -> 62972893 | E14: =SUMIFS(Monthly_Data!$G$2:$G$1441,Monthly_Data!$A$2:$A$1441,$A14,Monthly_Data!$E$2:$E$1441,2012,Monthly_Data!$F$2:$F$1441,1) -> 8154081.4 | F14: =(D14+E14*(IF(Assumptions!$D$9="Yes",DAY(EOMONTH(DATE(2012,2,1),0))/DAY(EOMONTH(EDATE(DATE(2012,2,1),-12),0)),1)-1))*(1+IF(B14="A",Assumptions!$C$5,IF(B14="B",Assumptions!$C$6,Assumptions!$C$7))) -> 64232351 | G14: =SUMIFS(Monthly_Data!$G$2:$G$1441,Monthly_Data!$A$2:$A$1441,$A14,Monthly_Data!$E$2:$E$1441,2013) -> 64009115 | H14: =G14-F14 -> -223236.12 | I14: =IFERROR(H14/F14,0) -> -0.0034754469 | J14: =RANK(I14,$I$5:$I$49) -> 36 | K14: =IF(H14>=0,"On / above","Below") -> Below | L14: =SUMIFS(Monthly_Data!$G$2:$G$1441,Monthly_Data!$A$2:$A$1441,$A14,Monthly_Data!$E$2:$E$1441,2012) -> 99025029 | M14: =IFERROR(L14/C14,0) -> 782.7323 | N14: =(L14+E14*(IF(Assumptions!$D$9="Yes",DAY(EOMONTH(DATE(2012,2,1),0))/DAY(EOMONTH(EDATE(DATE(2012,2,1),-12),0)),1)-1))*(1+IF(B14="A",Assumptions!$C$5,IF(B14="B",Assumptions!$C$6,Assumptions!$C$7))) -> 1.0100553e+08 | O14: =SUMIFS(Forecast_Data!$G$2:$G$237,Forecast_Data!$A$2:$A$237,"Store",Forecast_Data!$C$2:$C$237,$A14) -> 36645375 | P14: =G14+O14 -> 1.0065449e+08 | Q14: =P14-N14 -> -351039.35 | R14: =IFERROR(Q14/N14,0) -> -0.0034754469
A15: 11 | B15: A | C15: 207499 | D15: =SUMIFS(Monthly_Data!$G$2:$G$1441,Monthly_Data!$A$2:$A$1441,$A15,Monthly_Data!$E$2:$E$1441,2012,Monthly_Data!$F$2:$F$1441,"<=8") -> 45600041 | E15: =SUMIFS(Monthly_Data!$G$2:$G$1441,Monthly_Data!$A$2:$A$1441,$A15,Monthly_Data!$E$2:$E$1441,2012,Monthly_Data!$F$2:$F$1441,1) -> 5710634.1 | F15: =(D15+E15*(IF(Assumptions!$D$9="Yes",DAY(EOMONTH(DATE(2012,2,1),0))/DAY(EOMONTH(EDATE(DATE(2012,2,1),-12),0)),1)-1))*(1+IF(B15="A",Assumptions!$C$5,IF(B15="B",Assumptions!$C$6,Assumptions!$C$7))) -> 46968042 | G15: =SUMIFS(Monthly_Data!$G$2:$G$1441,Monthly_Data!$A$2:$A$1441,$A15,Monthly_Data!$E$2:$E$1441,2013) -> 47717711 | H15: =G15-F15 -> 749668.53 | I15: =IFERROR(H15/F15,0) -> 0.015961247 | J15: =RANK(I15,$I$5:$I$49) -> 21 | K15: =IF(H15>=0,"On / above","Below") -> On / above | L15: =SUMIFS(Monthly_Data!$G$2:$G$1441,Monthly_Data!$A$2:$A$1441,$A15,Monthly_Data!$E$2:$E$1441,2012) -> 70957676 | M15: =IFERROR(L15/C15,0) -> 341.96635 | N15: =(L15+E15*(IF(Assumptions!$D$9="Yes",DAY(EOMONTH(DATE(2012,2,1),0))/DAY(EOMONTH(EDATE(DATE(2012,2,1),-12),0)),1)-1))*(1+IF(B15="A",Assumptions!$C$5,IF(B15="B",Assumptions!$C$6,Assumptions!$C$7))) -> 73086406 | O15: =SUMIFS(Forecast_Data!$G$2:$G$237,Forecast_Data!$A$2:$A$237,"Store",Forecast_Data!$C$2:$C$237,$A15) -> 26535245 | P15: =G15+O15 -> 74252956 | Q15: =P15-N15 -> 1166550.2 | R15: =IFERROR(Q15/N15,0) -> 0.015961247
A16: 12 | B16: B | C16: 112238 | D16: =SUMIFS(Monthly_Data!$G$2:$G$1441,Monthly_Data!$A$2:$A$1441,$A16,Monthly_Data!$E$2:$E$1441,2012,Monthly_Data!$F$2:$F$1441,"<=8") -> 33934682 | E16: =SUMIFS(Monthly_Data!$G$2:$G$1441,Monthly_Data!$A$2:$A$1441,$A16,Monthly_Data!$E$2:$E$1441,2012,Monthly_Data!$F$2:$F$1441,1) -> 4323970 | F16: =(D16+E16*(IF(Assumptions!$D$9="Yes",DAY(EOMONTH(DATE(2012,2,1),0))/DAY(EOMONTH(EDATE(DATE(2012,2,1),-12),0)),1)-1))*(1+IF(B16="A",Assumptions!$C$5,IF(B16="B",Assumptions!$C$6,Assumptions!$C$7))) -> 34613375 | G16: =SUMIFS(Monthly_Data!$G$2:$G$1441,Monthly_Data!$A$2:$A$1441,$A16,Monthly_Data!$E$2:$E$1441,2013) -> 35603982 | H16: =G16-F16 -> 990606.33 | I16: =IFERROR(H16/F16,0) -> 0.028619177 | J16: =RANK(I16,$I$5:$I$49) -> 14 | K16: =IF(H16>=0,"On / above","Below") -> On / above | L16: =SUMIFS(Monthly_Data!$G$2:$G$1441,Monthly_Data!$A$2:$A$1441,$A16,Monthly_Data!$E$2:$E$1441,2012) -> 52896767 | M16: =IFERROR(L16/C16,0) -> 471.29107 | N16: =(L16+E16*(IF(Assumptions!$D$9="Yes",DAY(EOMONTH(DATE(2012,2,1),0))/DAY(EOMONTH(EDATE(DATE(2012,2,1),-12),0)),1)-1))*(1+IF(B16="A",Assumptions!$C$5,IF(B16="B",Assumptions!$C$6,Assumptions!$C$7))) -> 53954703 | O16: =SUMIFS(Forecast_Data!$G$2:$G$237,Forecast_Data!$A$2:$A$237,"Store",Forecast_Data!$C$2:$C$237,$A16) -> 19894860 | P16: =G16+O16 -> 55498842 | Q16: =P16-N16 -> 1544139.2 | R16: =IFERROR(Q16/N16,0) -> 0.028619177
... A49: 45 | B49: B | C49: 118221 | D49: =SUMIFS(Monthly_Data!$G$2:$G$1441,Monthly_Data!$A$2:$A$1441,$A49,Monthly_Data!$E$2:$E$1441,2012,Monthly_Data!$F$2:$F$1441,"<=8") -> 26296898 | E49: =SUMIFS(Monthly_Data!$G$2:$G$1441,Monthly_Data!$A$2:$A$1441,$A49,Monthly_Data!$E$2:$E$1441,2012,Monthly_Data!$F$2:$F$1441,1) -> 3062913.4 | F49: =(D49+E49*(IF(Assumptions!$D$9="Yes",DAY(EOMONTH(DATE(2012,2,1),0))/DAY(EOMONTH(EDATE(DATE(2012,2,1),-12),0)),1)-1))*(1+IF(B49="A",Assumptions!$C$5,IF(B49="B",Assumptions!$C$6,Assumptions!$C$7))) -> 26822836 | G49: =SUMIFS(Monthly_Data!$G$2:$G$1441,Monthly_Data!$A$2:$A$1441,$A49,Monthly_Data!$E$2:$E$1441,2013) -> 26838931 | H49: =G49-F49 -> 16095.196 | I49: =IFERROR(H49/F49,0) -> 0.00060005569 | J49: =RANK(I49,$I$5:$I$49) -> 31 | K49: =IF(H49>=0,"On / above","Below") -> On / above | L49: =SUMIFS(Monthly_Data!$G$2:$G$1441,Monthly_Data!$A$2:$A$1441,$A49,Monthly_Data!$E$2:$E$1441,2012) -> 41362057 | M49: =IFERROR(L49/C49,0) -> 349.87064 | N49: =(L49+E49*(IF(Assumptions!$D$9="Yes",DAY(EOMONTH(DATE(2012,2,1),0))/DAY(EOMONTH(EDATE(DATE(2012,2,1),-12),0)),1)-1))*(1+IF(B49="A",Assumptions!$C$5,IF(B49="B",Assumptions!$C$6,Assumptions!$C$7))) -> 42189298 | O49: =SUMIFS(Forecast_Data!$G$2:$G$237,Forecast_Data!$A$2:$A$237,"Store",Forecast_Data!$C$2:$C$237,$A49) -> 15375683 | P49: =G49+O49 -> 42214614 | Q49: =P49-N49 -> 25315.933 | R49: =IFERROR(Q49/N49,0) -> 0.0006000558
A50: Total | C50: =SUM(C5:C49) -> 5862942 | D50: =SUM(D5:D49) -> 1.5832144e+09 | E50: =SUM(E5:E49) -> 1.8668597e+08 | F50: =SUM(F5:F49) -> 1.6246239e+09 | G50: =SUM(G5:G49) -> 1.6341325e+09 | H50: =SUM(H5:H49) -> 9508682.1 | I50: =IFERROR(H50/F50,0) -> 0.0058528514 | K50: =COUNTIF(K5:K49,"On / above")&" of 45 on/above" -> 32 of 45 on/above | L50: =SUM(L5:L49) -> 2.4599452e+09 | N50: =SUM(N5:N49) -> 2.5242648e+09 | O50: =SUM(O5:O49) -> 9.057678e+08 | P50: =SUM(P5:P49) -> 2.5399003e+09 | Q50: =SUM(Q5:Q49) -> 15635553 | R50: =IFERROR(Q50/N50,0) -> 0.0061941017
A52: Tip: use the filter arrows on row 4 to sort stores by variance %. Store 14 is the largest $ shortfall.
A53: Summary by store type
A54: Type | B54: Stores | C54: Growth target | D54: YTD budget | E54: YTD actual | F54: YTD variance | G54: Variance % | H54: Full-year budget | I54: Latest estimate | J54: LE vs budget %
A55: A | B55: =COUNTIF($B$5:$B$49,A55) -> 22 | C55: =Assumptions!$C$5 -> 0.03 | D55: =SUMIFS($F$5:$F$49,$B$5:$B$49,$A55) -> 1.0533652e+09 | E55: =SUMIFS($G$5:$G$49,$B$5:$B$49,$A55) -> 1.0518203e+09 | F55: =SUMIFS($H$5:$H$49,$B$5:$B$49,$A55) -> -1544989.8 | G55: =IFERROR(F55/D55,0) -> -0.0014667181 | H55: =SUMIFS($N$5:$N$49,$B$5:$B$49,$A55) -> 1.6331729e+09 | I55: =SUMIFS($P$5:$P$49,$B$5:$B$49,$A55) -> 1.6315091e+09 | J55: =IFERROR(I55/H55-1,0) -> -0.0010187339
A56: B | B56: =COUNTIF($B$5:$B$49,A56) -> 17 | C56: =Assumptions!$C$6 -> 0.02 | D56: =SUMIFS($F$5:$F$49,$B$5:$B$49,$A56) -> 4.7347963e+08 | E56: =SUMIFS($G$5:$G$49,$B$5:$B$49,$A56) -> 4.8063663e+08 | F56: =SUMIFS($H$5:$H$49,$B$5:$B$49,$A56) -> 7156996.9 | G56: =IFERROR(F56/D56,0) -> 0.015115744 | H56: =SUMIFS($N$5:$N$49,$B$5:$B$49,$A56) -> 7.4180548e+08 | I56: =SUMIFS($P$5:$P$49,$B$5:$B$49,$A56) -> 7.5309642e+08 | J56: =IFERROR(I56/H56-1,0) -> 0.015220883
A57: C | B57: =COUNTIF($B$5:$B$49,A57) -> 6 | C57: =Assumptions!$C$7 -> 0.015 | D57: =SUMIFS($F$5:$F$49,$B$5:$B$49,$A57) -> 97778981 | E57: =SUMIFS($G$5:$G$49,$B$5:$B$49,$A57) -> 1.0167566e+08 | F57: =SUMIFS($H$5:$H$49,$B$5:$B$49,$A57) -> 3896675 | G57: =IFERROR(F57/D57,0) -> 0.039851868 | H57: =SUMIFS($N$5:$N$49,$B$5:$B$49,$A57) -> 1.4928641e+08 | I57: =SUMIFS($P$5:$P$49,$B$5:$B$49,$A57) -> 1.552948e+08 | J57: =IFERROR(I57/H57-1,0) -> 0.040247381

Sheet Dept_BvA
A1: Budget vs Actual by Department (YTD)
A2: Department budgets follow the same rule: LY actual by store type x (1 + growth target).
A4: Dept | B4: LY YTD - A | C4: LY YTD - B | D4: LY YTD - C | E4: YTD budget | F4: YTD actual | G4: Variance | H4: Variance % | I4: Abs. variance rank | K4: helper: |variance| | M4: Tip: filter or sort column I to see the departments that move the total most.
A5: 1 | B5: =SUMIFS(Dept_Data!$E$2:$E$6870,Dept_Data!$A$2:$A$6870,$A5,Dept_Data!$C$2:$C$6870,2012,Dept_Data!$D$2:$D$6870,"<=8",Dept_Data!$B$2:$B$6870,"A") -> 15915109 | C5: =SUMIFS(Dept_Data!$E$2:$E$6870,Dept_Data!$A$2:$A$6870,$A5,Dept_Data!$C$2:$C$6870,2012,Dept_Data!$D$2:$D$6870,"<=8",Dept_Data!$B$2:$B$6870,"B") -> 9690200.7 | D5: =SUMIFS(Dept_Data!$E$2:$E$6870,Dept_Data!$A$2:$A$6870,$A5,Dept_Data!$C$2:$C$6870,2012,Dept_Data!$D$2:$D$6870,"<=8",Dept_Data!$B$2:$B$6870,"C") -> 1729506 | E5: =B5*(1+Assumptions!$C$5)+C5*(1+Assumptions!$C$6)+D5*(1+Assumptions!$C$7) -> 28032015 | F5: =SUMIFS(Dept_Data!$E$2:$E$6870,Dept_Data!$A$2:$A$6870,$A5,Dept_Data!$C$2:$C$6870,2013) -> 28550471 | G5: =F5-E5 -> 518455.36 | H5: =IF(E5<=0,"",G5/E5) -> 0.018495115 | I5: =RANK(ABS(G5),$K$5:$K$85) -> 16 | K5: =ABS(G5) -> 518455.36 | M5: Note: budget here does not apply the trading-day factor (department detail is kept simple).
A6: 2 | B6: =SUMIFS(Dept_Data!$E$2:$E$6870,Dept_Data!$A$2:$A$6870,$A6,Dept_Data!$C$2:$C$6870,2012,Dept_Data!$D$2:$D$6870,"<=8",Dept_Data!$B$2:$B$6870,"A") -> 39659597 | C6: =SUMIFS(Dept_Data!$E$2:$E$6870,Dept_Data!$A$2:$A$6870,$A6,Dept_Data!$C$2:$C$6870,2012,Dept_Data!$D$2:$D$6870,"<=8",Dept_Data!$B$2:$B$6870,"B") -> 24989967 | D6: =SUMIFS(Dept_Data!$E$2:$E$6870,Dept_Data!$A$2:$A$6870,$A6,Dept_Data!$C$2:$C$6870,2012,Dept_Data!$D$2:$D$6870,"<=8",Dept_Data!$B$2:$B$6870,"C") -> 3002443.5 | E6: =B6*(1+Assumptions!$C$5)+C6*(1+Assumptions!$C$6)+D6*(1+Assumptions!$C$7) -> 69386632 | F6: =SUMIFS(Dept_Data!$E$2:$E$6870,Dept_Data!$A$2:$A$6870,$A6,Dept_Data!$C$2:$C$6870,2013) -> 69499747 | G6: =F6-E6 -> 113115.4 | H6: =IF(E6<=0,"",G6/E6) -> 0.0016302189 | I6: =RANK(ABS(G6),$K$5:$K$85) -> 55 | K6: =ABS(G6) -> 113115.4
A7: 3 | B7: =SUMIFS(Dept_Data!$E$2:$E$6870,Dept_Data!$A$2:$A$6870,$A7,Dept_Data!$C$2:$C$6870,2012,Dept_Data!$D$2:$D$6870,"<=8",Dept_Data!$B$2:$B$6870,"A") -> 11217053 | C7: =SUMIFS(Dept_Data!$E$2:$E$6870,Dept_Data!$A$2:$A$6870,$A7,Dept_Data!$C$2:$C$6870,2012,Dept_Data!$D$2:$D$6870,"<=8",Dept_Data!$B$2:$B$6870,"B") -> 8010896.7 | D7: =SUMIFS(Dept_Data!$E$2:$E$6870,Dept_Data!$A$2:$A$6870,$A7,Dept_Data!$C$2:$C$6870,2012,Dept_Data!$D$2:$D$6870,"<=8",Dept_Data!$B$2:$B$6870,"C") -> 185595.84 | E7: =B7*(1+Assumptions!$C$5)+C7*(1+Assumptions!$C$6)+D7*(1+Assumptions!$C$7) -> 19913059 | F7: =SUMIFS(Dept_Data!$E$2:$E$6870,Dept_Data!$A$2:$A$6870,$A7,Dept_Data!$C$2:$C$6870,2013) -> 20178948 | G7: =F7-E7 -> 265888.55 | H7: =IF(E7<=0,"",G7/E7) -> 0.013352471 | I7: =RANK(ABS(G7),$K$5:$K$85) -> 34 | K7: =ABS(G7) -> 265888.55
A8: 4 | B8: =SUMIFS(Dept_Data!$E$2:$E$6870,Dept_Data!$A$2:$A$6870,$A8,Dept_Data!$C$2:$C$6870,2012,Dept_Data!$D$2:$D$6870,"<=8",Dept_Data!$B$2:$B$6870,"A") -> 24784226 | C8: =SUMIFS(Dept_Data!$E$2:$E$6870,Dept_Data!$A$2:$A$6870,$A8,Dept_Data!$C$2:$C$6870,2012,Dept_Data!$D$2:$D$6870,"<=8",Dept_Data!$B$2:$B$6870,"B") -> 12445327 | D8: =SUMIFS(Dept_Data!$E$2:$E$6870,Dept_Data!$A$2:$A$6870,$A8,Dept_Data!$C$2:$C$6870,2012,Dept_Data!$D$2:$D$6870,"<=8",Dept_Data!$B$2:$B$6870,"C") -> 2755810.7 | E8: =B8*(1+Assumptions!$C$5)+C8*(1+Assumptions!$C$6)+D8*(1+Assumptions!$C$7) -> 41019134 | F8: =SUMIFS(Dept_Data!$E$2:$E$6870,Dept_Data!$A$2:$A$6870,$A8,Dept_Data!$C$2:$C$6870,2013) -> 41389463 | G8: =F8-E8 -> 370328.45 | H8: =IF(E8<=0,"",G8/E8) -> 0.0090281879 | I8: =RANK(ABS(G8),$K$5:$K$85) -> 23 | K8: =ABS(G8) -> 370328.45
A9: 5 | B9: =SUMIFS(Dept_Data!$E$2:$E$6870,Dept_Data!$A$2:$A$6870,$A9,Dept_Data!$C$2:$C$6870,2012,Dept_Data!$D$2:$D$6870,"<=8",Dept_Data!$B$2:$B$6870,"A") -> 17086777 | C9: =SUMIFS(Dept_Data!$E$2:$E$6870,Dept_Data!$A$2:$A$6870,$A9,Dept_Data!$C$2:$C$6870,2012,Dept_Data!$D$2:$D$6870,"<=8",Dept_Data!$B$2:$B$6870,"B") -> 10089435 | D9: =SUMIFS(Dept_Data!$E$2:$E$6870,Dept_Data!$A$2:$A$6870,$A9,Dept_Data!$C$2:$C$6870,2012,Dept_Data!$D$2:$D$6870,"<=8",Dept_Data!$B$2:$B$6870,"C") -> 125826.48 | E9: =B9*(1+Assumptions!$C$5)+C9*(1+Assumptions!$C$6)+D9*(1+Assumptions!$C$7) -> 28018317 | F9: =SUMIFS(Dept_Data!$E$2:$E$6870,Dept_Data!$A$2:$A$6870,$A9,Dept_Data!$C$2:$C$6870,2013) -> 26904336 | G9: =F9-E9 -> -1113981.5 | H9: =IF(E9<=0,"",G9/E9) -> -0.039759045 | I9: =RANK(ABS(G9),$K$5:$K$85) -> 10 | K9: =ABS(G9) -> 1113981.5
A10: 6 | B10: =SUMIFS(Dept_Data!$E$2:$E$6870,Dept_Data!$A$2:$A$6870,$A10,Dept_Data!$C$2:$C$6870,2012,Dept_Data!$D$2:$D$6870,"<=8",Dept_Data!$B$2:$B$6870,"A") -> 3430159.9 | C10: =SUMIFS(Dept_Data!$E$2:$E$6870,Dept_Data!$A$2:$A$6870,$A10,Dept_Data!$C$2:$C$6870,2012,Dept_Data!$D$2:$D$6870,"<=8",Dept_Data!$B$2:$B$6870,"B") -> 2646769.7 | D10: =SUMIFS(Dept_Data!$E$2:$E$6870,Dept_Data!$A$2:$A$6870,$A10,Dept_Data!$C$2:$C$6870,2012,Dept_Data!$D$2:$D$6870,"<=8",Dept_Data!$B$2:$B$6870,"C") -> 5467.58 | E10: =B10*(1+Assumptions!$C$5)+C10*(1+Assumptions!$C$6)+D10*(1+Assumptions!$C$7) -> 6238319.3 | F10: =SUMIFS(Dept_Data!$E$2:$E$6870,Dept_Data!$A$2:$A$6870,$A10,Dept_Data!$C$2:$C$6870,2013) -> 5019373.5 | G10: =F10-E10 -> -1218945.8 | H10: =IF(E10<=0,"",G10/E10) -> -0.19539651 | I10: =RANK(ABS(G10),$K$5:$K$85) -> 8 | K10: =ABS(G10) -> 1218945.8
A11: 7 | B11: =SUMIFS(Dept_Data!$E$2:$E$6870,Dept_Data!$A$2:$A$6870,$A11,Dept_Data!$C$2:$C$6870,2012,Dept_Data!$D$2:$D$6870,"<=8",Dept_Data!$B$2:$B$6870,"A") -> 19489021 | C11: =SUMIFS(Dept_Data!$E$2:$E$6870,Dept_Data!$A$2:$A$6870,$A11,Dept_Data!$C$2:$C$6870,2012,Dept_Data!$D$2:$D$6870,"<=8",Dept_Data!$B$2:$B$6870,"B") -> 11473927 | D11: =SUMIFS(Dept_Data!$E$2:$E$6870,Dept_Data!$A$2:$A$6870,$A11,Dept_Data!$C$2:$C$6870,2012,Dept_Data!$D$2:$D$6870,"<=8",Dept_Data!$B$2:$B$6870,"C") -> 114859.54 | E11: =B11*(1+Assumptions!$C$5)+C11*(1+Assumptions!$C$6)+D11*(1+Assumptions!$C$7) -> 31893679 | F11: =SUMIFS(Dept_Data!$E$2:$E$6870,Dept_Data!$A$2:$A$6870,$A11,Dept_Data!$C$2:$C$6870,2013) -> 32090589 | G11: =F11-E11 -> 196909.17 | H11: =IF(E11<=0,"",G11/E11) -> 0.0061739247 | I11: =RANK(ABS(G11),$K$5:$K$85) -> 43 | K11: =ABS(G11) -> 196909.17
A12: 8 | B12: =SUMIFS(Dept_Data!$E$2:$E$6870,Dept_Data!$A$2:$A$6870,$A12,Dept_Data!$C$2:$C$6870,2012,Dept_Data!$D$2:$D$6870,"<=8",Dept_Data!$B$2:$B$6870,"A") -> 27722399 | C12: =SUMIFS(Dept_Data!$E$2:$E$6870,Dept_Data!$A$2:$A$6870,$A12,Dept_Data!$C$2:$C$6870,2012,Dept_Data!$D$2:$D$6870,"<=8",Dept_Data!$B$2:$B$6870,"B") -> 15819558 | D12: =SUMIFS(Dept_Data!$E$2:$E$6870,Dept_Data!$A$2:$A$6870,$A12,Dept_Data!$C$2:$C$6870,2012,Dept_Data!$D$2:$D$6870,"<=8",Dept_Data!$B$2:$B$6870,"C") -> 2462259.9 | E12: =B12*(1+Assumptions!$C$5)+C12*(1+Assumptions!$C$6)+D12*(1+Assumptions!$C$7) -> 47189214 | F12: =SUMIFS(Dept_Data!$E$2:$E$6870,Dept_Data!$A$2:$A$6870,$A12,Dept_Data!$C$2:$C$6870,2013) -> 47606665 | G12: =F12-E12 -> 417451.28 | H12: =IF(E12<=0,"",G12/E12) -> 0.0088463284 | I12: =RANK(ABS(G12),$K$5:$K$85) -> 17 | K12: =ABS(G12) -> 417451.28
A13: 9 | B13: =SUMIFS(Dept_Data!$E$2:$E$6870,Dept_Data!$A$2:$A$6870,$A13,Dept_Data!$C$2:$C$6870,2012,Dept_Data!$D$2:$D$6870,"<=8",Dept_Data!$B$2:$B$6870,"A") -> 18317343 | C13: =SUMIFS(Dept_Data!$E$2:$E$6870,Dept_Data!$A$2:$A$6870,$A13,Dept_Data!$C$2:$C$6870,2012,Dept_Data!$D$2:$D$6870,"<=8",Dept_Data!$B$2:$B$6870,"B") -> 13713237 | D13: =SUMIFS(Dept_Data!$E$2:$E$6870,Dept_Data!$A$2:$A$6870,$A13,Dept_Data!$C$2:$C$6870,2012,Dept_Data!$D$2:$D$6870,"<=8",Dept_Data!$B$2:$B$6870,"C") -> 28148.32 | E13: =B13*(1+Assumptions!$C$5)+C13*(1+Assumptions!$C$6)+D13*(1+Assumptions!$C$7) -> 32882936 | F13: =SUMIFS(Dept_Data!$E$2:$E$6870,Dept_Data!$A$2:$A$6870,$A13,Dept_Data!$C$2:$C$6870,2013) -> 34508608 | G13: =F13-E13 -> 1625672.2 | H13: =IF(E13<=0,"",G13/E13) -> 0.049438171 | I13: =RANK(ABS(G13),$K$5:$K$85) -> 6 | K13: =ABS(G13) -> 1625672.2
A14: 10 | B14: =SUMIFS(Dept_Data!$E$2:$E$6870,Dept_Data!$A$2:$A$6870,$A14,Dept_Data!$C$2:$C$6870,2012,Dept_Data!$D$2:$D$6870,"<=8",Dept_Data!$B$2:$B$6870,"A") -> 18022848 | C14: =SUMIFS(Dept_Data!$E$2:$E$6870,Dept_Data!$A$2:$A$6870,$A14,Dept_Data!$C$2:$C$6870,2012,Dept_Data!$D$2:$D$6870,"<=8",Dept_Data!$B$2:$B$6870,"B") -> 10376972 | D14: =SUMIFS(Dept_Data!$E$2:$E$6870,Dept_Data!$A$2:$A$6870,$A14,Dept_Data!$C$2:$C$6870,2012,Dept_Data!$D$2:$D$6870,"<=8",Dept_Data!$B$2:$B$6870,"C") -> 70331.35 | E14: =B14*(1+Assumptions!$C$5)+C14*(1+Assumptions!$C$6)+D14*(1+Assumptions!$C$7) -> 29219431 | F14: =SUMIFS(Dept_Data!$E$2:$E$6870,Dept_Data!$A$2:$A$6870,$A14,Dept_Data!$C$2:$C$6870,2013) -> 29476354 | G14: =F14-E14 -> 256922.62 | H14: =IF(E14<=0,"",G14/E14) -> 0.0087928686 | I14: =RANK(ABS(G14),$K$5:$K$85) -> 35 | K14: =ABS(G14) -> 256922.62
A15: 11 | B15: =SUMIFS(Dept_Data!$E$2:$E$6870,Dept_Data!$A$2:$A$6870,$A15,Dept_Data!$C$2:$C$6870,2012,Dept_Data!$D$2:$D$6870,"<=8",Dept_Data!$B$2:$B$6870,"A") -> 12761516 | C15: =SUMIFS(Dept_Data!$E$2:$E$6870,Dept_Data!$A$2:$A$6870,$A15,Dept_Data!$C$2:$C$6870,2012,Dept_Data!$D$2:$D$6870,"<=8",Dept_Data!$B$2:$B$6870,"B") -> 9155083 | D15: =SUMIFS(Dept_Data!$E$2:$E$6870,Dept_Data!$A$2:$A$6870,$A15,Dept_Data!$C$2:$C$6870,2012,Dept_Data!$D$2:$D$6870,"<=8",Dept_Data!$B$2:$B$6870,"C") -> 174980.15 | E15: =B15*(1+Assumptions!$C$5)+C15*(1+Assumptions!$C$6)+D15*(1+Assumptions!$C$7) -> 22660151 | F15: =SUMIFS(Dept_Data!$E$2:$E$6870,Dept_Data!$A$2:$A$6870,$A15,Dept_Data!$C$2:$C$6870,2013) -> 22555856 | G15: =F15-E15 -> -104294.86 | H15: =IF(E15<=0,"",G15/E15) -> -0.0046025667 | I15: =RANK(ABS(G15),$K$5:$K$85) -> 57 | K15: =ABS(G15) -> 104294.86
A16: 12 | B16: =SUMIFS(Dept_Data!$E$2:$E$6870,Dept_Data!$A$2:$A$6870,$A16,Dept_Data!$C$2:$C$6870,2012,Dept_Data!$D$2:$D$6870,"<=8",Dept_Data!$B$2:$B$6870,"A") -> 4056750.1 | C16: =SUMIFS(Dept_Data!$E$2:$E$6870,Dept_Data!$A$2:$A$6870,$A16,Dept_Data!$C$2:$C$6870,2012,Dept_Data!$D$2:$D$6870,"<=8",Dept_Data!$B$2:$B$6870,"B") -> 2606542.7 | D16: =SUMIFS(Dept_Data!$E$2:$E$6870,Dept_Data!$A$2:$A$6870,$A16,Dept_Data!$C$2:$C$6870,2012,Dept_Data!$D$2:$D$6870,"<=8",Dept_Data!$B$2:$B$6870,"C") -> 17272.26 | E16: =B16*(1+Assumptions!$C$5)+C16*(1+Assumptions!$C$6)+D16*(1+Assumptions!$C$7) -> 6854657.5 | F16: =SUMIFS(Dept_Data!$E$2:$E$6870,Dept_Data!$A$2:$A$6870,$A16,Dept_Data!$C$2:$C$6870,2013) -> 6872884.3 | G16: =F16-E16 -> 18226.818 | H16: =IF(E16<=0,"",G16/E16) -> 0.0026590414 | I16: =RANK(ABS(G16),$K$5:$K$85) -> 69 | K16: =ABS(G16) -> 18226.818
A17: 13 | B17: =SUMIFS(Dept_Data!$E$2:$E$6870,Dept_Data!$A$2:$A$6870,$A17,Dept_Data!$C$2:$C$6870,2012,Dept_Data!$D$2:$D$6870,"<=8",Dept_Data!$B$2:$B$6870,"A") -> 28295452 | C17: =SUMIFS(Dept_Data!$E$2:$E$6870,Dept_Data!$A$2:$A$6870,$A17,Dept_Data!$C$2:$C$6870,2012,Dept_Data!$D$2:$D$6870,"<=8",Dept_Data!$B$2:$B$6870,"B") -> 16370860 | D17: =SUMIFS(Dept_Data!$E$2:$E$6870,Dept_Data!$A$2:$A$6870,$A17,Dept_Data!$C$2:$C$6870,2012,Dept_Data!$D$2:$D$6870,"<=8",Dept_Data!$B$2:$B$6870,"C") -> 2629213.7 | E17: =B17*(1+Assumptions!$C$5)+C17*(1+Assumptions!$C$6)+D17*(1+Assumptions!$C$7) -> 48511244 | F17: =SUMIFS(Dept_Data!$E$2:$E$6870,Dept_Data!$A$2:$A$6870,$A17,Dept_Data!$C$2:$C$6870,2013) -> 48277224 | G17: =F17-E17 -> -234020.06 | H17: =IF(E17<=0,"",G17/E17) -> -0.0048240375 | I17: =RANK(ABS(G17),$K$5:$K$85) -> 37 | K17: =ABS(G17) -> 234020.06
... A85: 99 | B85: =SUMIFS(Dept_Data!$E$2:$E$6870,Dept_Data!$A$2:$A$6870,$A85,Dept_Data!$C$2:$C$6870,2012,Dept_Data!$D$2:$D$6870,"<=8",Dept_Data!$B$2:$B$6870,"A") -> 32236.62 | C85: =SUMIFS(Dept_Data!$E$2:$E$6870,Dept_Data!$A$2:$A$6870,$A85,Dept_Data!$C$2:$C$6870,2012,Dept_Data!$D$2:$D$6870,"<=8",Dept_Data!$B$2:$B$6870,"B") -> 0 | D85: =SUMIFS(Dept_Data!$E$2:$E$6870,Dept_Data!$A$2:$A$6870,$A85,Dept_Data!$C$2:$C$6870,2012,Dept_Data!$D$2:$D$6870,"<=8",Dept_Data!$B$2:$B$6870,"C") -> 25.01 | E85: =B85*(1+Assumptions!$C$5)+C85*(1+Assumptions!$C$6)+D85*(1+Assumptions!$C$7) -> 33229.104 | F85: =SUMIFS(Dept_Data!$E$2:$E$6870,Dept_Data!$A$2:$A$6870,$A85,Dept_Data!$C$2:$C$6870,2013) -> 80996.9 | G85: =F85-E85 -> 47767.796 | H85: =IF(E85<=0,"",G85/E85) -> 1.4375289 | I85: =RANK(ABS(G85),$K$5:$K$85) -> 64 | K85: =ABS(G85) -> 47767.796
A86: Total | B86: =SUM(B5:B85) -> 1.0226847e+09 | C86: =SUM(C5:C85) -> 4.6419572e+08 | D86: =SUM(D5:D85) -> 96333971 | E86: =SUM(E5:E85) -> 1.6246239e+09 | F86: =SUM(F5:F85) -> 1.6341325e+09 | G86: =SUM(G5:G85) -> 9508682.1

Sheet Excel_Forecast
A1: Forecast in Excel: Seasonal Index x Trend
A2: Classic FP&A method built only with formulas. Compare its accuracy with the budget and Python's Holt-Winters.
A4: Month | B4: t | C4: FY | D4: Fiscal month | E4: Revenue | F4: Days | G4: Revenue / day | H4: Seasonal index | I4: Deseasonalised / day | J4: Trend (train to Jan 2012) | K4: Backtest forecast | L4: Abs % error | N4: Fiscal month | O4: Month | P4: Seasonal index
A5: 40210 | B5: 1 | C5: 2011 | D5: 1 | E5: =SUMIFS(Monthly_Data!$G$2:$G$1441,Monthly_Data!$E$2:$E$1441,C5,Monthly_Data!$F$2:$F$1441,D5) -> 1.8951033e+08 | F5: =DAY(EOMONTH(A5,0)) -> 28 | G5: =E5/F5 -> 6768226.2 | H5: =INDEX($P$5:$P$16,D5) -> 0.99715179 | I5: =G5/H5 -> 6787558.6 | J5: =FORECAST(B5,$I$5:$I$28,$B$5:$B$28) -> 6732749.8 | N5: 1 | O5: Feb | P5: =AVERAGE(INDEX($G$5:$G$16,N5)/AVERAGE($G$5:$G$16),INDEX($G$17:$G$28,N5)/AVERAGE($G$17:$G$28)) -> 0.99715179
A6: 40238 | B6: 2 | C6: 2011 | D6: 2 | E6: =SUMIFS(Monthly_Data!$G$2:$G$1441,Monthly_Data!$E$2:$E$1441,C6,Monthly_Data!$F$2:$F$1441,D6) -> 2.0454498e+08 | F6: =DAY(EOMONTH(A6,0)) -> 31 | G6: =E6/F6 -> 6598225 | H6: =INDEX($P$5:$P$16,D6) -> 0.9600817 | I6: =G6/H6 -> 6872566.2 | J6: =FORECAST(B6,$I$5:$I$28,$B$5:$B$28) -> 6733119.2 | N6: 2 | O6: Mar | P6: =AVERAGE(INDEX($G$5:$G$16,N6)/AVERAGE($G$5:$G$16),INDEX($G$17:$G$28,N6)/AVERAGE($G$17:$G$28)) -> 0.9600817
A7: 40269 | B7: 3 | C7: 2011 | D7: 3 | E7: =SUMIFS(Monthly_Data!$G$2:$G$1441,Monthly_Data!$E$2:$E$1441,C7,Monthly_Data!$F$2:$F$1441,D7) -> 1.9539535e+08 | F7: =DAY(EOMONTH(A7,0)) -> 30 | G7: =E7/F7 -> 6513178.2 | H7: =INDEX($P$5:$P$16,D7) -> 0.96820018 | I7: =G7/H7 -> 6727098.7 | J7: =FORECAST(B7,$I$5:$I$28,$B$5:$B$28) -> 6733488.5 | N7: 3 | O7: Apr | P7: =AVERAGE(INDEX($G$5:$G$16,N7)/AVERAGE($G$5:$G$16),INDEX($G$17:$G$28,N7)/AVERAGE($G$17:$G$28)) -> 0.96820018
A8: 40299 | B8: 4 | C8: 2011 | D8: 4 | E8: =SUMIFS(Monthly_Data!$G$2:$G$1441,Monthly_Data!$E$2:$E$1441,C8,Monthly_Data!$F$2:$F$1441,D8) -> 2.0822031e+08 | F8: =DAY(EOMONTH(A8,0)) -> 31 | G8: =E8/F8 -> 6716784.2 | H8: =INDEX($P$5:$P$16,D8) -> 0.98408319 | I8: =G8/H8 -> 6825423.1 | J8: =FORECAST(B8,$I$5:$I$28,$B$5:$B$28) -> 6733857.9 | N8: 4 | O8: May | P8: =AVERAGE(INDEX($G$5:$G$16,N8)/AVERAGE($G$5:$G$16),INDEX($G$17:$G$28,N8)/AVERAGE($G$17:$G$28)) -> 0.98408319
A9: 40330 | B9: 5 | C9: 2011 | D9: 5 | E9: =SUMIFS(Monthly_Data!$G$2:$G$1441,Monthly_Data!$E$2:$E$1441,C9,Monthly_Data!$F$2:$F$1441,D9) -> 2.0567786e+08 | F9: =DAY(EOMONTH(A9,0)) -> 30 | G9: =E9/F9 -> 6855928.6 | H9: =INDEX($P$5:$P$16,D9) -> 1.0102527 | I9: =G9/H9 -> 6786350.2 | J9: =FORECAST(B9,$I$5:$I$28,$B$5:$B$28) -> 6734227.2 | N9: 5 | O9: Jun | P9: =AVERAGE(INDEX($G$5:$G$16,N9)/AVERAGE($G$5:$G$16),INDEX($G$17:$G$28,N9)/AVERAGE($G$17:$G$28)) -> 1.0102527
A10: 40360 | B10: 6 | C10: 2011 | D10: 6 | E10: =SUMIFS(Monthly_Data!$G$2:$G$1441,Monthly_Data!$E$2:$E$1441,C10,Monthly_Data!$F$2:$F$1441,D10) -> 2.0452549e+08 | F10: =DAY(EOMONTH(A10,0)) -> 31 | G10: =E10/F10 -> 6597596.6 | H10: =INDEX($P$5:$P$16,D10) -> 0.97529481 | I10: =G10/H10 -> 6764720.3 | J10: =FORECAST(B10,$I$5:$I$28,$B$5:$B$28) -> 6734596.6 | N10: 6 | O10: Jul | P10: =AVERAGE(INDEX($G$5:$G$16,N10)/AVERAGE($G$5:$G$16),INDEX($G$17:$G$28,N10)/AVERAGE($G$17:$G$28)) -> 0.97529481
A11: 40391 | B11: 7 | C11: 2011 | D11: 7 | E11: =SUMIFS(Monthly_Data!$G$2:$G$1441,Monthly_Data!$E$2:$E$1441,C11,Monthly_Data!$F$2:$F$1441,D11) -> 2.0772183e+08 | F11: =DAY(EOMONTH(A11,0)) -> 31 | G11: =E11/F11 -> 6700704.2 | H11: =INDEX($P$5:$P$16,D11) -> 0.99358549 | I11: =G11/H11 -> 6743963.4 | J11: =FORECAST(B11,$I$5:$I$28,$B$5:$B$28) -> 6734965.9 | N11: 7 | O11: Aug | P11: =AVERAGE(INDEX($G$5:$G$16,N11)/AVERAGE($G$5:$G$16),INDEX($G$17:$G$28,N11)/AVERAGE($G$17:$G$28)) -> 0.99358549
A12: 40422 | B12: 8 | C12: 2011 | D12: 8 | E12: =SUMIFS(Monthly_Data!$G$2:$G$1441,Monthly_Data!$E$2:$E$1441,C12,Monthly_Data!$F$2:$F$1441,D12) -> 1.8650536e+08 | F12: =DAY(EOMONTH(A12,0)) -> 30 | G12: =E12/F12 -> 6216845.2 | H12: =INDEX($P$5:$P$16,D12) -> 0.92756612 | I12: =G12/H12 -> 6702320.3 | J12: =FORECAST(B12,$I$5:$I$28,$B$5:$B$28) -> 6735335.3 | N12: 8 | O12: Sep | P12: =AVERAGE(INDEX($G$5:$G$16,N12)/AVERAGE($G$5:$G$16),INDEX($G$17:$G$28,N12)/AVERAGE($G$17:$G$28)) -> 0.92756612
A13: 40452 | B13: 9 | C13: 2011 | D13: 9 | E13: =SUMIFS(Monthly_Data!$G$2:$G$1441,Monthly_Data!$E$2:$E$1441,C13,Monthly_Data!$F$2:$F$1441,D13) -> 1.9403678e+08 | F13: =DAY(EOMONTH(A13,0)) -> 31 | G13: =E13/F13 -> 6259251 | H13: =INDEX($P$5:$P$16,D13) -> 0.95320325 | I13: =G13/H13 -> 6566544 | J13: =FORECAST(B13,$I$5:$I$28,$B$5:$B$28) -> 6735704.6 | N13: 9 | O13: Oct | P13: =AVERAGE(INDEX($G$5:$G$16,N13)/AVERAGE($G$5:$G$16),INDEX($G$17:$G$28,N13)/AVERAGE($G$17:$G$28)) -> 0.95320325
A14: 40483 | B14: 10 | C14: 2011 | D14: 10 | E14: =SUMIFS(Monthly_Data!$G$2:$G$1441,Monthly_Data!$E$2:$E$1441,C14,Monthly_Data!$F$2:$F$1441,D14) -> 2.1829225e+08 | F14: =DAY(EOMONTH(A14,0)) -> 30 | G14: =E14/F14 -> 7276408.3 | H14: =INDEX($P$5:$P$16,D14) -> 1.0956393 | I14: =G14/H14 -> 6641244.2 | J14: =FORECAST(B14,$I$5:$I$28,$B$5:$B$28) -> 6736074 | N14: 10 | O14: Nov | P14: =AVERAGE(INDEX($G$5:$G$16,N14)/AVERAGE($G$5:$G$16),INDEX($G$17:$G$28,N14)/AVERAGE($G$17:$G$28)) -> 1.0956393
A15: 40513 | B15: 11 | C15: 2011 | D15: 11 | E15: =SUMIFS(Monthly_Data!$G$2:$G$1441,Monthly_Data!$E$2:$E$1441,C15,Monthly_Data!$F$2:$F$1441,D15) -> 2.6024109e+08 | F15: =DAY(EOMONTH(A15,0)) -> 31 | G15: =E15/F15 -> 8394873.8 | H15: =INDEX($P$5:$P$16,D15) -> 1.243645 | I15: =G15/H15 -> 6750217.3 | J15: =FORECAST(B15,$I$5:$I$28,$B$5:$B$28) -> 6736443.3 | N15: 11 | O15: Dec | P15: =AVERAGE(INDEX($G$5:$G$16,N15)/AVERAGE($G$5:$G$16),INDEX($G$17:$G$28,N15)/AVERAGE($G$17:$G$28)) -> 1.243645
